<?xml version="1.0"?>
<robot name="storm_robot" xmlns:xacro="http://www.ros.org/wiki/xacro">

  <xacro:include filename="$(find velodyne_description)/urdf/VLP-16.urdf.xacro"/>

  <!-- ===== Links ===== -->

  <link name="base_footprint"/>

  <link name="base_link">
    <visual>
      <origin xyz="0 0 0" rpy="0 0 0"/>
      <geometry><box size="0.6 0.4 0.3"/></geometry>
      <material name="grey"><color rgba="0.5 0.5 0.5 1"/></material>
    </visual>
    <collision>
      <origin xyz="0 0 0" rpy="0 0 0"/>
      <geometry><box size="0.6 0.4 0.3"/></geometry>
    </collision>
    <inertial>
      <mass value="20.0"/>
      <origin xyz="0 0 0"/>
      <inertia ixx="0.5" ixy="0" ixz="0" iyy="0.5" iyz="0" izz="0.5"/>
    </inertial>
  </link>

  <joint name="base_footprint_joint" type="fixed">
    <parent link="base_footprint"/>
    <child link="base_link"/>
    <origin xyz="0 0 0.15" rpy="0 0 0"/>
  </joint>

  <!-- Left wheel -->
  <link name="wheel_left_link">
    <visual>
      <origin xyz="0 0 0" rpy="1.5708 0 0"/>
      <geometry><cylinder radius="0.1" length="0.05"/></geometry>
      <material name="black"><color rgba="0.1 0.1 0.1 1"/></material>
    </visual>
    <collision>
      <origin xyz="0 0 0" rpy="1.5708 0 0"/>
      <geometry><cylinder radius="0.1" length="0.05"/></geometry>
    </collision>
    <inertial>
      <mass value="1.0"/>
      <inertia ixx="0.003" ixy="0" ixz="0" iyy="0.003" iyz="0" izz="0.005"/>
    </inertial>
  </link>

  <joint name="wheel_left_joint" type="continuous">
    <parent link="base_link"/>
    <child link="wheel_left_link"/>
    <origin xyz="0 0.2 -0.05" rpy="0 0 0"/>
    <axis xyz="0 1 0"/>
  </joint>

  <!-- Right wheel -->
  <link name="wheel_right_link">
    <visual>
      <origin xyz="0 0 0" rpy="1.5708 0 0"/>
      <geometry><cylinder radius="0.1" length="0.05"/></geometry>
      <material name="black"/>
    </visual>
    <collision>
      <origin xyz="0 0 0" rpy="1.5708 0 0"/>
      <geometry><cylinder radius="0.1" length="0.05"/></geometry>
    </collision>
    <inertial>
      <mass value="1.0"/>
      <inertia ixx="0.003" ixy="0" ixz="0" iyy="0.003" iyz="0" izz="0.005"/>
    </inertial>
  </link>

  <joint name="wheel_right_joint" type="continuous">
    <parent link="base_link"/>
    <child link="wheel_right_link"/>
    <origin xyz="0 -0.2 -0.05" rpy="0 0 0"/>
    <axis xyz="0 1 0"/>
  </joint>

  <!-- Caster (passive front wheel for stability) -->
  <link name="caster_link">
    <visual>
      <geometry><sphere radius="0.05"/></geometry>
      <material name="grey"/>
    </visual>
    <collision>
      <geometry><sphere radius="0.05"/></geometry>
    </collision>
    <inertial>
      <mass value="0.5"/>
      <inertia ixx="0.001" ixy="0" ixz="0" iyy="0.001" iyz="0" izz="0.001"/>
    </inertial>
  </link>

  <joint name="caster_joint" type="fixed">
    <parent link="base_link"/>
    <child link="caster_link"/>
    <origin xyz="0.25 0 -0.1" rpy="0 0 0"/>
  </joint>

  <!-- VLP-16: mounted 0.876m above base_link to match real hardware offset -->
  <xacro:VLP-16 parent="base_link" name="velodyne" topic="/velodyne_points"
                hz="10" samples="1800" gpu="true">
    <origin xyz="0 0 0.876" rpy="0 0 0"/>
  </xacro:VLP-16>

  <!-- ===== Gazebo plugins ===== -->

  <!-- Differential drive: publishes odom and odom->base_link TF -->
  <gazebo>
    <plugin filename="gz-sim-diff-drive-system"
            name="gz::sim::systems::DiffDrive">
      <left_joint>wheel_left_joint</left_joint>
      <right_joint>wheel_right_joint</right_joint>
      <wheel_separation>0.4</wheel_separation>
      <wheel_radius>0.1</wheel_radius>
      <odom_publish_frequency>20</odom_publish_frequency>
      <topic>cmd_vel</topic>
      <odom_topic>odom</odom_topic>
      <tf_topic>tf</tf_topic>
      <frame_id>odom</frame_id>
      <child_frame_id>base_link</child_frame_id>
      <min_velocity>-2</min_velocity>
      <max_velocity>2</max_velocity>
      <min_acceleration>-1</min_acceleration>
      <max_acceleration>1</max_acceleration>
    </plugin>
  </gazebo>

  <!-- Joint state publisher: needed by robot_state_publisher -->
  <gazebo>
    <plugin filename="gz-sim-joint-state-publisher-system"
            name="gz::sim::systems::JointStatePublisher">
      <topic>joint_states</topic>
    </plugin>
  </gazebo>

  <!-- Caster friction set to near-zero so it doesn't resist turning -->
  <gazebo reference="caster_link">
    <mu1>0.0</mu1>
    <mu2>0.0</mu2>
  </gazebo>

  <!-- VLP16 GPU LiDAR sensor override: 16-beam, ±15°, 0.3–25m, 10Hz -->
  <gazebo reference="velodyne">
    <sensor name="vlp16" type="gpu_lidar">
      <topic>/velodyne_points</topic>
      <update_rate>10</update_rate>
      <gz_frame_id>velodyne</gz_frame_id>
      <lidar>
        <scan>
          <horizontal>
            <samples>1800</samples>
            <resolution>1</resolution>
            <min_angle>-3.14159265</min_angle>
            <max_angle>3.14159265</max_angle>
          </horizontal>
          <vertical>
            <samples>16</samples>
            <resolution>1</resolution>
            <min_angle>-0.26179939</min_angle>
            <max_angle>0.26179939</max_angle>
          </vertical>
        </scan>
        <range>
          <min>0.3</min>
          <max>25.0</max>
          <resolution>0.001</resolution>
        </range>
        <noise>
          <type>gaussian</type>
          <mean>0.0</mean>
          <stddev>0.01</stddev>
        </noise>
      </lidar>
      <visualize>false</visualize>
      <always_on>true</always_on>
    </sensor>
  </gazebo>

</robot>
